Workbook
Name lst_Categorias: 'Relatórios'!$L$30:$L$36
Name lst_Tipos: 'Relatórios'!$O$30:$O$31
Name lst_Responsaveis: 'Relatórios'!$P$30:$P$35
Name lst_Meses: 'Relatórios'!$A$6:$A$11
Name lst_Codigos: OFFSET('Produtos'!$A$5,0,0,MAX(1,COUNTA('Produtos'!$A$5:$A$204)),1)

Sheet Dashboard
B2: EO | D2: Almox EO | P2: MÊS DE ANÁLISE | T2: Out/2025 | W2: DADOS DEMONSTRATIVOS
D3: Gestão Inteligente de Estoque | P3: PERÍODO DOS DADOS | T3: =MIN('Movimentações'!$A$5:$A$1004) | V3: a | W3: =MAX('Movimentações'!$A$5:$A$1004)
D4: Organização + Controle + Resultados | P4: ÚLTIMA MOVIMENTAÇÃO | T4: =MAX('Movimentações'!$A$5:$A$1004) | V4: registrada na aba Movimentações
B7: PRODUTOS CADASTRADOS | F7: VALOR EM ESTOQUE | J7: ITENS EM ALERTA | N7: ENTRADAS NO MÊS | R7: SAÍDAS NO MÊS | V7: MOVIMENTAÇÕES
B8: =COUNTA('Produtos'!$A$5:$A$204) | F8: =SUM('Estoque'!$K$5:$K$204) | J8: =COUNTIF('Estoque'!$L$5:$L$204,"REPOR")+COUNTIF('Estoque'!$L$5:$L$204,"CRÍTICO") | N8: =IFERROR(INDEX('Relatórios'!$D$6:$D$11,MATCH($T$2,'Relatórios'!$A$6:$A$11,0)),0) | R8: =IFERROR(INDEX('Relatórios'!$E$6:$E$11,MATCH($T$2,'Relatórios'!$A$6:$A$11,0)),0) | V8: =COUNTA('Movimentações'!$B$5:$B$1004)
B9: itens ativos no cadastro | F9: saldo atual × custo unitário | J9: ="Crítico: "&COUNTIF('Estoque'!$L$5:$L$204,"CRÍTICO")&" · Repor: "&COUNTIF('Estoque'!$L$5:$L$204,"REPOR") | N9: ="unidades recebidas em "&$T$2 | R9: ="unidades retiradas em "&$T$2 | V9: registros no histórico
B29: ALERTAS DE REPOSIÇÃO | N29: MOVIMENTAÇÕES RECENTES
B30: CÓDIGO | C30: PRODUTO | G30: SALDO | H30: MÍNIMO | I30: SUGERIDO | K30: STATUS | N30: DATA | P30: CÓDIGO | Q30: PRODUTO | U30: TIPO | W30: QTD. | X30: RESPONSÁVEL
B31: ='Relatórios'!N6 | C31: =IF(COUNT('Estoque'!$O$5:$O$204)=0,"Nenhum produto precisa de reposição no momento.",'Relatórios'!O6) | G31: ='Relatórios'!P6 | H31: ='Relatórios'!Q6 | I31: ='Relatórios'!R6 | K31: ='Relatórios'!S6 | N31: ='Relatórios'!N18 | P31: ='Relatórios'!O18 | Q31: ='Relatórios'!P18 | U31: ='Relatórios'!Q18 | W31: ='Relatórios'!R18 | X31: ='Relatórios'!S18
B32: ='Relatórios'!N7 | C32: ='Relatórios'!O7 | G32: ='Relatórios'!P7 | H32: ='Relatórios'!Q7 | I32: ='Relatórios'!R7 | K32: ='Relatórios'!S7 | N32: ='Relatórios'!N19 | P32: ='Relatórios'!O19 | Q32: ='Relatórios'!P19 | U32: ='Relatórios'!Q19 | W32: ='Relatórios'!R19 | X32: ='Relatórios'!S19
B33: ='Relatórios'!N8 | C33: ='Relatórios'!O8 | G33: ='Relatórios'!P8 | H33: ='Relatórios'!Q8 | I33: ='Relatórios'!R8 | K33: ='Relatórios'!S8 | N33: ='Relatórios'!N20 | P33: ='Relatórios'!O20 | Q33: ='Relatórios'!P20 | U33: ='Relatórios'!Q20 | W33: ='Relatórios'!R20 | X33: ='Relatórios'!S20
B34: ='Relatórios'!N9 | C34: ='Relatórios'!O9 | G34: ='Relatórios'!P9 | H34: ='Relatórios'!Q9 | I34: ='Relatórios'!R9 | K34: ='Relatórios'!S9 | N34: ='Relatórios'!N21 | P34: ='Relatórios'!O21 | Q34: ='Relatórios'!P21 | U34: ='Relatórios'!Q21 | W34: ='Relatórios'!R21 | X34: ='Relatórios'!S21
B35: ='Relatórios'!N10 | C35: ='Relatórios'!O10 | G35: ='Relatórios'!P10 | H35: ='Relatórios'!Q10 | I35: ='Relatórios'!R10 | K35: ='Relatórios'!S10 | N35: ='Relatórios'!N22 | P35: ='Relatórios'!O22 | Q35: ='Relatórios'!P22 | U35: ='Relatórios'!Q22 | W35: ='Relatórios'!R22 | X35: ='Relatórios'!S22
B36: ='Relatórios'!N11 | C36: ='Relatórios'!O11 | G36: ='Relatórios'!P11 | H36: ='Relatórios'!Q11 | I36: ='Relatórios'!R11 | K36: ='Relatórios'!S11 | N36: ='Relatórios'!N23 | P36: ='Relatórios'!O23 | Q36: ='Relatórios'!P23 | U36: ='Relatórios'!Q23 | W36: ='Relatórios'!R23 | X36: ='Relatórios'!S23
B37: ='Relatórios'!N12 | C37: ='Relatórios'!O12 | G37: ='Relatórios'!P12 | H37: ='Relatórios'!Q12 | I37: ='Relatórios'!R12 | K37: ='Relatórios'!S12 | N37: ='Relatórios'!N24 | P37: ='Relatórios'!O24 | Q37: ='Relatórios'!P24 | U37: ='Relatórios'!Q24 | W37: ='Relatórios'!R24 | X37: ='Relatórios'!S24
B38: ='Relatórios'!N13 | C38: ='Relatórios'!O13 | G38: ='Relatórios'!P13 | H38: ='Relatórios'!Q13 | I38: ='Relatórios'!R13 | K38: ='Relatórios'!S13 | N38: ='Relatórios'!N25 | P38: ='Relatórios'!O25 | Q38: ='Relatórios'!P25 | U38: ='Relatórios'!Q25 | W38: ='Relatórios'!R25 | X38: ='Relatórios'!S25
B40: Projeto de portfólio · Elinaldo Oliveira · Todos os dados são fictícios e demonstrativos · Veja a aba Leia-me

Sheet Produtos
A1: Almox EO · Cadastro de Produtos
A2: Cadastre cada item em uma linha. Códigos únicos (P001…), categoria pela lista, quantidades inteiras ≥ 0. Capacidade: 200 produtos.
A3: Legenda: | B3: Branco = digitar dados | C3: Cinza-azulado = fórmula (não editar)
A4: Código do produto | B4: Nome do produto | C4: Categoria | D4: Fornecedor | E4: Custo unitário (R$) | F4: Estoque inicial | G4: Estoque mínimo | H4: Estoque máximo | I4: Localização
A5: P001 | B5: Cabo drop 1 fibra (bobina 1 km) | C5: Fibra Óptica | D5: LumenFibra Cabos | E5: 389.9 | F5: 14 | G5: 6 | H5: 20 | I5: A-01-01
A6: P002 | B6: Conector rápido SC/APC | C6: Fibra Óptica | D6: LumenFibra Cabos | E6: 3.2 | F6: 400 | G6: 150 | H6: 600 | I6: A-01-02
A7: P003 | B7: Splitter óptico 1x8 | C7: Fibra Óptica | D7: OptiLink Componentes | E7: 42.5 | F7: 40 | G7: 15 | H7: 60 | I7: A-01-03
A8: P004 | B8: Caixa de terminação óptica 16P | C8: Fibra Óptica | D8: OptiLink Componentes | E8: 118 | F8: 18 | G8: 8 | H8: 30 | I8: A-02-01
A9: P005 | B9: Tubete protetor de emenda | C9: Fibra Óptica | D9: OptiLink Componentes | E9: 0.35 | F9: 900 | G9: 300 | H9: 1500 | I9: A-02-02
A10: P006 | B10: ONU GPON Wi-Fi dual band | C10: Equipamentos de Rede | D10: NetPoint Distribuidora | E10: 189 | F10: 60 | G10: 25 | H10: 90 | I10: B-01-01
A11: P007 | B11: Roteador Wi-Fi 6 | C11: Equipamentos de Rede | D11: NetPoint Distribuidora | E11: 245 | F11: 25 | G11: 10 | H11: 40 | I11: B-01-02
A12: P008 | B12: Patch cord óptico SC/APC 2 m | C12: Equipamentos de Rede | D12: OptiLink Componentes | E12: 9.8 | F12: 150 | G12: 60 | H12: 250 | I12: B-01-03
A13: P009 | B13: Fonte 12V 1A para ONU | C13: Equipamentos de Rede | D13: NetPoint Distribuidora | E13: 14.5 | F13: 50 | G13: 20 | H13: 80 | I13: B-02-01
A14: P010 | B14: Clivador de precisão | C14: Ferramentas | D14: Ferramax Industrial | E14: 680 | F14: 6 | G14: 3 | H14: 8 | I14: C-01-01
A15: P011 | B15: Alicate decapador de fibra | C15: Ferramentas | D15: Ferramax Industrial | E15: 95 | F15: 10 | G15: 4 | H15: 14 | I15: C-01-02
A16: P012 | B16: Kit limpeza óptica | C16: Ferramentas | D16: OptiLink Componentes | E16: 64 | F16: 12 | G16: 5 | H16: 18 | I16: C-01-03
... A34: P030 | B34: Álcool isopropílico 1 L | C34: Escritório e Limpeza | D34: Higiclean Distribuidora | E34: 29.5 | F34: 24 | G34: 10 | H34: 36 | I34: G-01-03

Sheet Movimentações
A1: Almox EO · Movimentações
A2: Registre cada entrada ou saída em uma nova linha. O nome do produto e o saldo são preenchidos automaticamente. Capacidade: 1.000 registros. | H2: Próximo ID: | I2: ="MOV-"&TEXT(COUNTA($B$5:$B$1004)+1,"0000")
A3: Legenda: | B3: Branco = digitar dados | C3: Cinza-azulado = fórmula (não editar)
A4: Data | B4: ID da movimentação | C4: Código do produto | D4: Nome do produto | E4: Tipo de movimentação | F4: Quantidade | G4: Responsável | H4: Observação | I4: Saldo do produto no fim do dia | J4: Chave de ordenação (auxiliar)
A5: 45782 | B5: MOV-0001 | C5: P011 | D5: =IF(C5="","",IFERROR(INDEX('Produtos'!$B$5:$B$204,MATCH(C5,'Produtos'!$A$5:$A$204,0)),"Código não cadastrado")) | E5: Saída | F5: 2 | G5: Elinaldo Oliveira | H5: Saída para equipe de campo | I5: =IF(OR(A5="",C5=""),"",IFERROR(INDEX('Produtos'!$F$5:$F$204,MATCH(C5,'Produtos'!$A$5:$A$204,0))+SUMIFS($F$5:$F$1004,$C$5:$C$1004,C5,$E$5:$E$1004,"Entrada",$A$5:$A$1004,"<="&A5)-SUMIFS($F$5:$F$1004,$C$5:$C$1004,C5,$E$5:$E$1004,"Saída",$A$5:$A$1004,"<="&A5),"")) | J5: =IF(A5="","",A5+ROW()/100000)
A6: 45783 | B6: MOV-0002 | C6: P001 | D6: =IF(C6="","",IFERROR(INDEX('Produtos'!$B$5:$B$204,MATCH(C6,'Produtos'!$A$5:$A$204,0)),"Código não cadastrado")) | E6: Saída | F6: 9 | G6: Rodrigo Oliveira | H6: Saída para equipe de campo | I6: =IF(OR(A6="",C6=""),"",IFERROR(INDEX('Produtos'!$F$5:$F$204,MATCH(C6,'Produtos'!$A$5:$A$204,0))+SUMIFS($F$5:$F$1004,$C$5:$C$1004,C6,$E$5:$E$1004,"Entrada",$A$5:$A$1004,"<="&A6)-SUMIFS($F$5:$F$1004,$C$5:$C$1004,C6,$E$5:$E$1004,"Saída",$A$5:$A$1004,"<="&A6),"")) | J6: =IF(A6="","",A6+ROW()/100000)
A7: 45784 | B7: MOV-0003 | C7: P006 | D7: =IF(C7="","",IFERROR(INDEX('Produtos'!$B$5:$B$204,MATCH(C7,'Produtos'!$A$5:$A$204,0)),"Código não cadastrado")) | E7: Saída | F7: 41 | G7: Rodrigo Oliveira | H7: Instalação em cliente | I7: =IF(OR(A7="",C7=""),"",IFERROR(INDEX('Produtos'!$F$5:$F$204,MATCH(C7,'Produtos'!$A$5:$A$204,0))+SUMIFS($F$5:$F$1004,$C$5:$C$1004,C7,$E$5:$E$1004,"Entrada",$A$5:$A$1004,"<="&A7)-SUMIFS($F$5:$F$1004,$C$5:$C$1004,C7,$E$5:$E$1004,"Saída",$A$5:$A$1004,"<="&A7),"")) | J7: =IF(A7="","",A7+ROW()/100000)
A8: 45784 | B8: MOV-0004 | C8: P011 | D8: =IF(C8="","",IFERROR(INDEX('Produtos'!$B$5:$B$204,MATCH(C8,'Produtos'!$A$5:$A$204,0)),"Código não cadastrado")) | E8: Saída | F8: 2 | G8: Elinaldo Oliveira | H8: Substituição de ferramenta | I8: =IF(OR(A8="",C8=""),"",IFERROR(INDEX('Produtos'!$F$5:$F$204,MATCH(C8,'Produtos'!$A$5:$A$204,0))+SUMIFS($F$5:$F$1004,$C$5:$C$1004,C8,$E$5:$E$1004,"Entrada",$A$5:$A$1004,"<="&A8)-SUMIFS($F$5:$F$1004,$C$5:$C$1004,C8,$E$5:$E$1004,"Saída",$A$5:$A$1004,"<="&A8),"")) | J8: =IF(A8="","",A8+ROW()/100000)
A9: 45785 | B9: MOV-0005 | C9: P018 | D9: =IF(C9="","",IFERROR(INDEX('Produtos'!$B$5:$B$204,MATCH(C9,'Produtos'!$A$5:$A$204,0)),"Código não cadastrado")) | E9: Saída | F9: 9 | G9: Rosilene Barbosa | H9: Expedição de pedido | I9: =IF(OR(A9="",C9=""),"",IFERROR(INDEX('Produtos'!$F$5:$F$204,MATCH(C9,'Produtos'!$A$5:$A$204,0))+SUMIFS($F$5:$F$1004,$C$5:$C$1004,C9,$E$5:$E$1004,"Entrada",$A$5:$A$1004,"<="&A9)-SUMIFS($F$5:$F$1004,$C$5:$C$1004,C9,$E$5:$E$1004,"Saída",$A$5:$A$1004,"<="&A9),"")) | J9: =IF(A9="","",A9+ROW()/100000)
A10: 45786 | B10: MOV-0006 | C10: P001 | D10: =IF(C10="","",IFERROR(INDEX('Produtos'!$B$5:$B$204,MATCH(C10,'Produtos'!$A$5:$A$204,0)),"Código não cadastrado")) | E10: Entrada | F10: 15 | G10: Bruno Estevam | H10: Recebimento de fornecedor | I10: =IF(OR(A10="",C10=""),"",IFERROR(INDEX('Produtos'!$F$5:$F$204,MATCH(C10,'Produtos'!$A$5:$A$204,0))+SUMIFS($F$5:$F$1004,$C$5:$C$1004,C10,$E$5:$E$1004,"Entrada",$A$5:$A$1004,"<="&A10)-SUMIFS($F$5:$F$1004,$C$5:$C$1004,C10,$E$5:$E$1004,"Saída",$A$5:$A$1004,"<="&A10),"")) | J10: =IF(A10="","",A10+ROW()/100000)
A11: 45786 | B11: MOV-0007 | C11: P022 | D11: =IF(C11="","",IFERROR(INDEX('Produtos'!$B$5:$B$204,MATCH(C11,'Produtos'!$A$5:$A$204,0)),"Código não cadastrado")) | E11: Saída | F11: 1 | G11: Bruno Estevam | H11: Entrega de EPI a colaborador | I11: =IF(OR(A11="",C11=""),"",IFERROR(INDEX('Produtos'!$F$5:$F$204,MATCH(C11,'Produtos'!$A$5:$A$204,0))+SUMIFS($F$5:$F$1004,$C$5:$C$1004,C11,$E$5:$E$1004,"Entrada",$A$5:$A$1004,"<="&A11)-SUMIFS($F$5:$F$1004,$C$5:$C$1004,C11,$E$5:$E$1004,"Saída",$A$5:$A$1004,"<="&A11),"")) | J11: =IF(A11="","",A11+ROW()/100000)
A12: 45787 | B12: MOV-0008 | C12: P003 | D12: =IF(C12="","",IFERROR(INDEX('Produtos'!$B$5:$B$204,MATCH(C12,'Produtos'!$A$5:$A$204,0)),"Código não cadastrado")) | E12: Saída | F12: 14 | G12: Rodrigo Oliveira | H12: Instalação em cliente | I12: =IF(OR(A12="",C12=""),"",IFERROR(INDEX('Produtos'!$F$5:$F$204,MATCH(C12,'Produtos'!$A$5:$A$204,0))+SUMIFS($F$5:$F$1004,$C$5:$C$1004,C12,$E$5:$E$1004,"Entrada",$A$5:$A$1004,"<="&A12)-SUMIFS($F$5:$F$1004,$C$5:$C$1004,C12,$E$5:$E$1004,"Saída",$A$5:$A$1004,"<="&A12),"")) | J12: =IF(A12="","",A12+ROW()/100000)
A13: 45790 | B13: MOV-0009 | C13: P027 | D13: =IF(C13="","",IFERROR(INDEX('Produtos'!$B$5:$B$204,MATCH(C13,'Produtos'!$A$5:$A$204,0)),"Código não cadastrado")) | E13: Saída | F13: 6 | G13: Rodrigo Oliveira | H13: Saída para equipe de campo | I13: =IF(OR(A13="",C13=""),"",IFERROR(INDEX('Produtos'!$F$5:$F$204,MATCH(C13,'Produtos'!$A$5:$A$204,0))+SUMIFS($F$5:$F$1004,$C$5:$C$1004,C13,$E$5:$E$1004,"Entrada",$A$5:$A$1004,"<="&A13)-SUMIFS($F$5:$F$1004,$C$5:$C$1004,C13,$E$5:$E$1004,"Saída",$A$5:$A$1004,"<="&A13),"")) | J13: =IF(A13="","",A13+ROW()/100000)
A14: 45791 | B14: MOV-0010 | C14: P006 | D14: =IF(C14="","",IFERROR(INDEX('Produtos'!$B$5:$B$204,MATCH(C14,'Produtos'!$A$5:$A$204,0)),"Código não cadastrado")) | E14: Entrada | F14: 71 | G14: Elinaldo Oliveira | H14: Recebimento de fornecedor | I14: =IF(OR(A14="",C14=""),"",IFERROR(INDEX('Produtos'!$F$5:$F$204,MATCH(C14,'Produtos'!$A$5:$A$204,0))+SUMIFS($F$5:$F$1004,$C$5:$C$1004,C14,$E$5:$E$1004,"Entrada",$A$5:$A$1004,"<="&A14)-SUMIFS($F$5:$F$1004,$C$5:$C$1004,C14,$E$5:$E$1004,"Saída",$A$5:$A$1004,"<="&A14),"")) | J14: =IF(A14="","",A14+ROW()/100000)
A15: 45794 | B15: MOV-0011 | C15: P016 | D15: =IF(C15="","",IFERROR(INDEX('Produtos'!$B$5:$B$204,MATCH(C15,'Produtos'!$A$5:$A$204,0)),"Código não cadastrado")) | E15: Saída | F15: 29 | G15: Rosilene Barbosa | H15: Expedição de pedido | I15: =IF(OR(A15="",C15=""),"",IFERROR(INDEX('Produtos'!$F$5:$F$204,MATCH(C15,'Produtos'!$A$5:$A$204,0))+SUMIFS($F$5:$F$1004,$C$5:$C$1004,C15,$E$5:$E$1004,"Entrada",$A$5:$A$1004,"<="&A15)-SUMIFS($F$5:$F$1004,$C$5:$C$1004,C15,$E$5:$E$1004,"Saída",$A$5:$A$1004,"<="&A15),"")) | J15: =IF(A15="","",A15+ROW()/100000)
A16: 45794 | B16: MOV-0012 | C16: P028 | D16: =IF(C16="","",IFERROR(INDEX('Produtos'!$B$5:$B$204,MATCH(C16,'Produtos'!$A$5:$A$204,0)),"Código não cadastrado")) | E16: Saída | F16: 13 | G16: Rosilene Barbosa | H16: Consumo interno | I16: =IF(OR(A16="",C16=""),"",IFERROR(INDEX('Produtos'!$F$5:$F$204,MATCH(C16,'Produtos'!$A$5:$A$204,0))+SUMIFS($F$5:$F$1004,$C$5:$C$1004,C16,$E$5:$E$1004,"Entrada",$A$5:$A$1004,"<="&A16)-SUMIFS($F$5:$F$1004,$C$5:$C$1004,C16,$E$5:$E$1004,"Saída",$A$5:$A$1004,"<="&A16),"")) | J16: =IF(A16="","",A16+ROW()/100000)
... A162: 45960 | B162: MOV-0158 | C162: P017 | D162: =IF(C162="","",IFERROR(INDEX('Produtos'!$B$5:$B$204,MATCH(C162,'Produtos'!$A$5:$A$204,0)),"Código não cadastrado")) | E162: Saída | F162: 85 | G162: Rosilene Barbosa | H162: Expedição de pedido | I162: =IF(OR(A162="",C162=""),"",IFERROR(INDEX('Produtos'!$F$5:$F$204,MATCH(C162,'Produtos'!$A$5:$A$204,0))+SUMIFS($F$5:$F$1004,$C$5:$C$1004,C162,$E$5:$E$1004,"Entrada",$A$5:$A$1004,"<="&A162)-SUMIFS($F$5:$F$1004,$C$5:$C$1004,C162,$E$5:$E$1004,"Saída",$A$5:$A$1004,"<="&A162),"")) | J162: =IF(A162="","",A162+ROW()/100000)
D163: =IF(C163="","",IFERROR(INDEX('Produtos'!$B$5:$B$204,MATCH(C163,'Produtos'!$A$5:$A$204,0)),"Código não cadastrado")) | I163: =IF(OR(A163="",C163=""),"",IFERROR(INDEX('Produtos'!$F$5:$F$204,MATCH(C163,'Produtos'!$A$5:$A$204,0))+SUMIFS($F$5:$F$1004,$C$5:$C$1004,C163,$E$5:$E$1004,"Entrada",$A$5:$A$1004,"<="&A163)-SUMIFS($F$5:$F$1004,$C$5:$C$1004,C163,$E$5:$E$1004,"Saída",$A$5:$A$1004,"<="&A163),"")) | J163: =IF(A163="","",A163+ROW()/100000)
D164: =IF(C164="","",IFERROR(INDEX('Produtos'!$B$5:$B$204,MATCH(C164,'Produtos'!$A$5:$A$204,0)),"Código não cadastrado")) | I164: =IF(OR(A164="",C164=""),"",IFERROR(INDEX('Produtos'!$F$5:$F$204,MATCH(C164,'Produtos'!$A$5:$A$204,0))+SUMIFS($F$5:$F$1004,$C$5:$C$1004,C164,$E$5:$E$1004,"Entrada",$A$5:$A$1004,"<="&A164)-SUMIFS($F$5:$F$1004,$C$5:$C$1004,C164,$E$5:$E$1004,"Saída",$A$5:$A$1004,"<="&A164),"")) | J164: =IF(A164="","",A164+ROW()/100000)
D165: =IF(C165="","",IFERROR(INDEX('Produtos'!$B$5:$B$204,MATCH(C165,'Produtos'!$A$5:$A$204,0)),"Código não cadastrado")) | I165: =IF(OR(A165="",C165=""),"",IFERROR(INDEX('Produtos'!$F$5:$F$204,MATCH(C165,'Produtos'!$A$5:$A$204,0))+SUMIFS($F$5:$F$1004,$C$5:$C$1004,C165,$E$5:$E$1004,"Entrada",$A$5:$A$1004,"<="&A165)-SUMIFS($F$5:$F$1004,$C$5:$C$1004,C165,$E$5:$E$1004,"Saída",$A$5:$A$1004,"<="&A165),"")) | J165: =IF(A165="","",A165+ROW()/100000)
D166: =IF(C166="","",IFERROR(INDEX('Produtos'!$B$5:$B$204,MATCH(C166,'Produtos'!$A$5:$A$204,0)),"Código não cadastrado")) | I166: =IF(OR(A166="",C166=""),"",IFERROR(INDEX('Produtos'!$F$5:$F$204,MATCH(C166,'Produtos'!$A$5:$A$204,0))+SUMIFS($F$5:$F$1004,$C$5:$C$1004,C166,$E$5:$E$1004,"Entrada",$A$5:$A$1004,"<="&A166)-SUMIFS($F$5:$F$1004,$C$5:$C$1004,C166,$E$5:$E$1004,"Saída",$A$5:$A$1004,"<="&A166),"")) | J166: =IF(A166="","",A166+ROW()/100000)
D167: =IF(C167="","",IFERROR(INDEX('Produtos'!$B$5:$B$204,MATCH(C167,'Produtos'!$A$5:$A$204,0)),"Código não cadastrado")) | I167: =IF(OR(A167="",C167=""),"",IFERROR(INDEX('Produtos'!$F$5:$F$204,MATCH(C167,'Produtos'!$A$5:$A$204,0))+SUMIFS($F$5:$F$1004,$C$5:$C$1004,C167,$E$5:$E$1004,"Entrada",$A$5:$A$1004,"<="&A167)-SUMIFS($F$5:$F$1004,$C$5:$C$1004,C167,$E$5:$E$1004,"Saída",$A$5:$A$1004,"<="&A167),"")) | J167: =IF(A167="","",A167+ROW()/100000)
D168: =IF(C168="","",IFERROR(INDEX('Produtos'!$B$5:$B$204,MATCH(C168,'Produtos'!$A$5:$A$204,0)),"Código não cadastrado")) | I168: =IF(OR(A168="",C168=""),"",IFERROR(INDEX('Produtos'!$F$5:$F$204,MATCH(C168,'Produtos'!$A$5:$A$204,0))+SUMIFS($F$5:$F$1004,$C$5:$C$1004,C168,$E$5:$E$1004,"Entrada",$A$5:$A$1004,"<="&A168)-SUMIFS($F$5:$F$1004,$C$5:$C$1004,C168,$E$5:$E$1004,"Saída",$A$5:$A$1004,"<="&A168),"")) | J168: =IF(A168="","",A168+ROW()/100000)
D169: =IF(C169="","",IFERROR(INDEX('Produtos'!$B$5:$B$204,MATCH(C169,'Produtos'!$A$5:$A$204,0)),"Código não cadastrado")) | I169: =IF(OR(A169="",C169=""),"",IFERROR(INDEX('Produtos'!$F$5:$F$204,MATCH(C169,'Produtos'!$A$5:$A$204,0))+SUMIFS($F$5:$F$1004,$C$5:$C$1004,C169,$E$5:$E$1004,"Entrada",$A$5:$A$1004,"<="&A169)-SUMIFS($F$5:$F$1004,$C$5:$C$1004,C169,$E$5:$E$1004,"Saída",$A$5:$A$1004,"<="&A169),"")) | J169: =IF(A169="","",A169+ROW()/100000)
D170: =IF(C170="","",IFERROR(INDEX('Produtos'!$B$5:$B$204,MATCH(C170,'Produtos'!$A$5:$A$204,0)),"Código não cadastrado")) | I170: =IF(OR(A170="",C170=""),"",IFERROR(INDEX('Produtos'!$F$5:$F$204,MATCH(C170,'Produtos'!$A$5:$A$204,0))+SUMIFS($F$5:$F$1004,$C$5:$C$1004,C170,$E$5:$E$1004,"Entrada",$A$5:$A$1004,"<="&A170)-SUMIFS($F$5:$F$1004,$C$5:$C$1004,C170,$E$5:$E$1004,"Saída",$A$5:$A$1004,"<="&A170),"")) | J170: =IF(A170="","",A170+ROW()/100000)
D171: =IF(C171="","",IFERROR(INDEX('Produtos'!$B$5:$B$204,MATCH(C171,'Produtos'!$A$5:$A$204,0)),"Código não cadastrado")) | I171: =IF(OR(A171="",C171=""),"",IFERROR(INDEX('Produtos'!$F$5:$F$204,MATCH(C171,'Produtos'!$A$5:$A$204,0))+SUMIFS($F$5:$F$1004,$C$5:$C$1004,C171,$E$5:$E$1004,"Entrada",$A$5:$A$1004,"<="&A171)-SUMIFS($F$5:$F$1004,$C$5:$C$1004,C171,$E$5:$E$1004,"Saída",$A$5:$A$1004,"<="&A171),"")) | J171: =IF(A171="","",A171+ROW()/100000)
D172: =IF(C172="","",IFERROR(INDEX('Produtos'!$B$5:$B$204,MATCH(C172,'Produtos'!$A$5:$A$204,0)),"Código não cadastrado")) | I172: =IF(OR(A172="",C172=""),"",IFERROR(INDEX('Produtos'!$F$5:$F$204,MATCH(C172,'Produtos'!$A$5:$A$204,0))+SUMIFS($F$5:$F$1004,$C$5:$C$1004,C172,$E$5:$E$1004,"Entrada",$A$5:$A$1004,"<="&A172)-SUMIFS($F$5:$F$1004,$C$5:$C$1004,C172,$E$5:$E$1004,"Saída",$A$5:$A$1004,"<="&A172),"")) | J172: =IF(A172="","",A172+ROW()/100000)
D173: =IF(C173="","",IFERROR(INDEX('Produtos'!$B$5:$B$204,MATCH(C173,'Produtos'!$A$5:$A$204,0)),"Código não cadastrado")) | I173: =IF(OR(A173="",C173=""),"",IFERROR(INDEX('Produtos'!$F$5:$F$204,MATCH(C173,'Produtos'!$A$5:$A$204,0))+SUMIFS($F$5:$F$1004,$C$5:$C$1004,C173,$E$5:$E$1004,"Entrada",$A$5:$A$1004,"<="&A173)-SUMIFS($F$5:$F$1004,$C$5:$C$1004,C173,$E$5:$E$1004,"Saída",$A$5:$A$1004,"<="&A173),"")) | J173: =IF(A173="","",A173+ROW()/100000)
D174: =IF(C174="","",IFERROR(INDEX('Produtos'!$B$5:$B$204,MATCH(C174,'Produtos'!$A$5:$A$204,0)),"Código não cadastrado")) | I174: =IF(OR(A174="",C174=""),"",IFERROR(INDEX('Produtos'!$F$5:$F$204,MATCH(C174,'Produtos'!$A$5:$A$204,0))+SUMIFS($F$5:$F$1004,$C$5:$C$1004,C174,$E$5:$E$1004,"Entrada",$A$5:$A$1004,"<="&A174)-SUMIFS($F$5:$F$1004,$C$5:$C$1004,C174,$E$5:$E$1004,"Saída",$A$5:$A$1004,"<="&A174),"")) | J174: =IF(A174="","",A174+ROW()/100000)
... D1004: =IF(C1004="","",IFERROR(INDEX('Produtos'!$B$5:$B$204,MATCH(C1004,'Produtos'!$A$5:$A$204,0)),"Código não cadastrado")) | I1004: =IF(OR(A1004="",C1004=""),"",IFERROR(INDEX('Produtos'!$F$5:$F$204,MATCH(C1004,'Produtos'!$A$5:$A$204,0))+SUMIFS($F$5:$F$1004,$C$5:$C$1004,C1004,$E$5:$E$1004,"Entrada",$A$5:$A$1004,"<="&A1004)-SUMIFS($F$5:$F$1004,$C$5:$C$1004,C1004,$E$5:$E$1004,"Saída",$A$5:$A$1004,"<="&A1004),"")) | J1004: =IF(A1004="","",A1004+ROW()/100000)

Sheet Estoque
A1: Almox EO · Posição de Estoque
A2: Aba 100% calculada a partir de Produtos e Movimentações. Não digite aqui. Use os filtros do cabeçalho para consultar.
A3: Legenda: | B3: Branco = digitar dados | C3: Cinza-azulado = fórmula (não editar)
A4: Código | B4: Produto | C4: Categoria | D4: Estoque inicial | E4: Total de entradas | F4: Total de saídas | G4: Saldo atual | H4: Estoque mínimo | I4: Estoque máximo | J4: Custo unitário (R$) | K4: Valor total em estoque (R$) | L4: Status | M4: Quantidade sugerida para reposição | N4: Cobertura (saldo ÷ mínimo) | O4: Chave de alerta (auxiliar)
A5: =IF('Produtos'!A5="","",'Produtos'!A5) | B5: =IF(A5="","",'Produtos'!B5) | C5: =IF(A5="","",'Produtos'!C5) | D5: =IF(A5="","",'Produtos'!F5) | E5: =IF(A5="","",SUMIFS('Movimentações'!$F$5:$F$1004,'Movimentações'!$C$5:$C$1004,A5,'Movimentações'!$E$5:$E$1004,"Entrada")) | F5: =IF(A5="","",SUMIFS('Movimentações'!$F$5:$F$1004,'Movimentações'!$C$5:$C$1004,A5,'Movimentações'!$E$5:$E$1004,"Saída")) | G5: =IF(A5="","",D5+E5-F5) | H5: =IF(A5="","",'Produtos'!G5) | I5: =IF(A5="","",'Produtos'!H5) | J5: =IF(A5="","",'Produtos'!E5) | K5: =IF(A5="","",G5*J5) | L5: =IF(A5="","",IF(G5<=0,"CRÍTICO",IF(G5<=H5,"REPOR","OK"))) | M5: =IF(A5="","",IF(L5="OK",0,MAX(0,I5-G5))) | N5: =IF(A5="","",IF(H5>0,G5/H5,99)) | O5: =IF(A5="","",IF(L5="OK","",N5+ROW()/100000))
A6: =IF('Produtos'!A6="","",'Produtos'!A6) | B6: =IF(A6="","",'Produtos'!B6) | C6: =IF(A6="","",'Produtos'!C6) | D6: =IF(A6="","",'Produtos'!F6) | E6: =IF(A6="","",SUMIFS('Movimentações'!$F$5:$F$1004,'Movimentações'!$C$5:$C$1004,A6,'Movimentações'!$E$5:$E$1004,"Entrada")) | F6: =IF(A6="","",SUMIFS('Movimentações'!$F$5:$F$1004,'Movimentações'!$C$5:$C$1004,A6,'Movimentações'!$E$5:$E$1004,"Saída")) | G6: =IF(A6="","",D6+E6-F6) | H6: =IF(A6="","",'Produtos'!G6) | I6: =IF(A6="","",'Produtos'!H6) | J6: =IF(A6="","",'Produtos'!E6) | K6: =IF(A6="","",G6*J6) | L6: =IF(A6="","",IF(G6<=0,"CRÍTICO",IF(G6<=H6,"REPOR","OK"))) | M6: =IF(A6="","",IF(L6="OK",0,MAX(0,I6-G6))) | N6: =IF(A6="","",IF(H6>0,G6/H6,99)) | O6: =IF(A6="","",IF(L6="OK","",N6+ROW()/100000))
A7: =IF('Produtos'!A7="","",'Produtos'!A7) | B7: =IF(A7="","",'Produtos'!B7) | C7: =IF(A7="","",'Produtos'!C7) | D7: =IF(A7="","",'Produtos'!F7) | E7: =IF(A7="","",SUMIFS('Movimentações'!$F$5:$F$1004,'Movimentações'!$C$5:$C$1004,A7,'Movimentações'!$E$5:$E$1004,"Entrada")) | F7: =IF(A7="","",SUMIFS('Movimentações'!$F$5:$F$1004,'Movimentações'!$C$5:$C$1004,A7,'Movimentações'!$E$5:$E$1004,"Saída")) | G7: =IF(A7="","",D7+E7-F7) | H7: =IF(A7="","",'Produtos'!G7) | I7: =IF(A7="","",'Produtos'!H7) | J7: =IF(A7="","",'Produtos'!E7) | K7: =IF(A7="","",G7*J7) | L7: =IF(A7="","",IF(G7<=0,"CRÍTICO",IF(G7<=H7,"REPOR","OK"))) | M7: =IF(A7="","",IF(L7="OK",0,MAX(0,I7-G7))) | N7: =IF(A7="","",IF(H7>0,G7/H7,99)) | O7: =IF(A7="","",IF(L7="OK","",N7+ROW()/100000))
A8: =IF('Produtos'!A8="","",'Produtos'!A8) | B8: =IF(A8="","",'Produtos'!B8) | C8: =IF(A8="","",'Produtos'!C8) | D8: =IF(A8="","",'Produtos'!F8) | E8: =IF(A8="","",SUMIFS('Movimentações'!$F$5:$F$1004,'Movimentações'!$C$5:$C$1004,A8,'Movimentações'!$E$5:$E$1004,"Entrada")) | F8: =IF(A8="","",SUMIFS('Movimentações'!$F$5:$F$1004,'Movimentações'!$C$5:$C$1004,A8,'Movimentações'!$E$5:$E$1004,"Saída")) | G8: =IF(A8="","",D8+E8-F8) | H8: =IF(A8="","",'Produtos'!G8) | I8: =IF(A8="","",'Produtos'!H8) | J8: =IF(A8="","",'Produtos'!E8) | K8: =IF(A8="","",G8*J8) | L8: =IF(A8="","",IF(G8<=0,"CRÍTICO",IF(G8<=H8,"REPOR","OK"))) | M8: =IF(A8="","",IF(L8="OK",0,MAX(0,I8-G8))) | N8: =IF(A8="","",IF(H8>0,G8/H8,99)) | O8: =IF(A8="","",IF(L8="OK","",N8+ROW()/100000))
A9: =IF('Produtos'!A9="","",'Produtos'!A9) | B9: =IF(A9="","",'Produtos'!B9) | C9: =IF(A9="","",'Produtos'!C9) | D9: =IF(A9="","",'Produtos'!F9) | E9: =IF(A9="","",SUMIFS('Movimentações'!$F$5:$F$1004,'Movimentações'!$C$5:$C$1004,A9,'Movimentações'!$E$5:$E$1004,"Entrada")) | F9: =IF(A9="","",SUMIFS('Movimentações'!$F$5:$F$1004,'Movimentações'!$C$5:$C$1004,A9,'Movimentações'!$E$5:$E$1004,"Saída")) | G9: =IF(A9="","",D9+E9-F9) | H9: =IF(A9="","",'Produtos'!G9) | I9: =IF(A9="","",'Produtos'!H9) | J9: =IF(A9="","",'Produtos'!E9) | K9: =IF(A9="","",G9*J9) | L9: =IF(A9="","",IF(G9<=0,"CRÍTICO",IF(G9<=H9,"REPOR","OK"))) | M9: =IF(A9="","",IF(L9="OK",0,MAX(0,I9-G9))) | N9: =IF(A9="","",IF(H9>0,G9/H9,99)) | O9: =IF(A9="","",IF(L9="OK","",N9+ROW()/100000))
A10: =IF('Produtos'!A10="","",'Produtos'!A10) | B10: =IF(A10="","",'Produtos'!B10) | C10: =IF(A10="","",'Produtos'!C10) | D10: =IF(A10="","",'Produtos'!F10) | E10: =IF(A10="","",SUMIFS('Movimentações'!$F$5:$F$1004,'Movimentações'!$C$5:$C$1004,A10,'Movimentações'!$E$5:$E$1004,"Entrada")) | F10: =IF(A10="","",SUMIFS('Movimentações'!$F$5:$F$1004,'Movimentações'!$C$5:$C$1004,A10,'Movimentações'!$E$5:$E$1004,"Saída")) | G10: =IF(A10="","",D10+E10-F10) | H10: =IF(A10="","",'Produtos'!G10) | I10: =IF(A10="","",'Produtos'!H10) | J10: =IF(A10="","",'Produtos'!E10) | K10: =IF(A10="","",G10*J10) | L10: =IF(A10="","",IF(G10<=0,"CRÍTICO",IF(G10<=H10,"REPOR","OK"))) | M10: =IF(A10="","",IF(L10="OK",0,MAX(0,I10-G10))) | N10: =IF(A10="","",IF(H10>0,G10/H10,99)) | O10: =IF(A10="","",IF(L10="OK","",N10+ROW()/100000))
A11: =IF('Produtos'!A11="","",'Produtos'!A11) | B11: =IF(A11="","",'Produtos'!B11) | C11: =IF(A11="","",'Produtos'!C11) | D11: =IF(A11="","",'Produtos'!F11) | E11: =IF(A11="","",SUMIFS('Movimentações'!$F$5:$F$1004,'Movimentações'!$C$5:$C$1004,A11,'Movimentações'!$E$5:$E$1004,"Entrada")) | F11: =IF(A11="","",SUMIFS('Movimentações'!$F$5:$F$1004,'Movimentações'!$C$5:$C$1004,A11,'Movimentações'!$E$5:$E$1004,"Saída")) | G11: =IF(A11="","",D11+E11-F11) | H11: =IF(A11="","",'Produtos'!G11) | I11: =IF(A11="","",'Produtos'!H11) | J11: =IF(A11="","",'Produtos'!E11) | K11: =IF(A11="","",G11*J11) | L11: =IF(A11="","",IF(G11<=0,"CRÍTICO",IF(G11<=H11,"REPOR","OK"))) | M11: =IF(A11="","",IF(L11="OK",0,MAX(0,I11-G11))) | N11: =IF(A11="","",IF(H11>0,G11/H11,99)) | O11: =IF(A11="","",IF(L11="OK","",N11+ROW()/100000))
A12: =IF('Produtos'!A12="","",'Produtos'!A12) | B12: =IF(A12="","",'Produtos'!B12) | C12: =IF(A12="","",'Produtos'!C12) | D12: =IF(A12="","",'Produtos'!F12) | E12: =IF(A12="","",SUMIFS('Movimentações'!$F$5:$F$1004,'Movimentações'!$C$5:$C$1004,A12,'Movimentações'!$E$5:$E$1004,"Entrada")) | F12: =IF(A12="","",SUMIFS('Movimentações'!$F$5:$F$1004,'Movimentações'!$C$5:$C$1004,A12,'Movimentações'!$E$5:$E$1004,"Saída")) | G12: =IF(A12="","",D12+E12-F12) | H12: =IF(A12="","",'Produtos'!G12) | I12: =IF(A12="","",'Produtos'!H12) | J12: =IF(A12="","",'Produtos'!E12) | K12: =IF(A12="","",G12*J12) | L12: =IF(A12="","",IF(G12<=0,"CRÍTICO",IF(G12<=H12,"REPOR","OK"))) | M12: =IF(A12="","",IF(L12="OK",0,MAX(0,I12-G12))) | N12: =IF(A12="","",IF(H12>0,G12/H12,99)) | O12: =IF(A12="","",IF(L12="OK","",N12+ROW()/100000))
A13: =IF('Produtos'!A13="","",'Produtos'!A13) | B13: =IF(A13="","",'Produtos'!B13) | C13: =IF(A13="","",'Produtos'!C13) | D13: =IF(A13="","",'Produtos'!F13) | E13: =IF(A13="","",SUMIFS('Movimentações'!$F$5:$F$1004,'Movimentações'!$C$5:$C$1004,A13,'Movimentações'!$E$5:$E$1004,"Entrada")) | F13: =IF(A13="","",SUMIFS('Movimentações'!$F$5:$F$1004,'Movimentações'!$C$5:$C$1004,A13,'Movimentações'!$E$5:$E$1004,"Saída")) | G13: =IF(A13="","",D13+E13-F13) | H13: =IF(A13="","",'Produtos'!G13) | I13: =IF(A13="","",'Produtos'!H13) | J13: =IF(A13="","",'Produtos'!E13) | K13: =IF(A13="","",G13*J13) | L13: =IF(A13="","",IF(G13<=0,"CRÍTICO",IF(G13<=H13,"REPOR","OK"))) | M13: =IF(A13="","",IF(L13="OK",0,MAX(0,I13-G13))) | N13: =IF(A13="","",IF(H13>0,G13/H13,99)) | O13: =IF(A13="","",IF(L13="OK","",N13+ROW()/100000))
A14: =IF('Produtos'!A14="","",'Produtos'!A14) | B14: =IF(A14="","",'Produtos'!B14) | C14: =IF(A14="","",'Produtos'!C14) | D14: =IF(A14="","",'Produtos'!F14) | E14: =IF(A14="","",SUMIFS('Movimentações'!$F$5:$F$1004,'Movimentações'!$C$5:$C$1004,A14,'Movimentações'!$E$5:$E$1004,"Entrada")) | F14: =IF(A14="","",SUMIFS('Movimentações'!$F$5:$F$1004,'Movimentações'!$C$5:$C$1004,A14,'Movimentações'!$E$5:$E$1004,"Saída")) | G14: =IF(A14="","",D14+E14-F14) | H14: =IF(A14="","",'Produtos'!G14) | I14: =IF(A14="","",'Produtos'!H14) | J14: =IF(A14="","",'Produtos'!E14) | K14: =IF(A14="","",G14*J14) | L14: =IF(A14="","",IF(G14<=0,"CRÍTICO",IF(G14<=H14,"REPOR","OK"))) | M14: =IF(A14="","",IF(L14="OK",0,MAX(0,I14-G14))) | N14: =IF(A14="","",IF(H14>0,G14/H14,99)) | O14: =IF(A14="","",IF(L14="OK","",N14+ROW()/100000))
A15: =IF('Produtos'!A15="","",'Produtos'!A15) | B15: =IF(A15="","",'Produtos'!B15) | C15: =IF(A15="","",'Produtos'!C15) | D15: =IF(A15="","",'Produtos'!F15) | E15: =IF(A15="","",SUMIFS('Movimentações'!$F$5:$F$1004,'Movimentações'!$C$5:$C$1004,A15,'Movimentações'!$E$5:$E$1004,"Entrada")) | F15: =IF(A15="","",SUMIFS('Movimentações'!$F$5:$F$1004,'Movimentações'!$C$5:$C$1004,A15,'Movimentações'!$E$5:$E$1004,"Saída")) | G15: =IF(A15="","",D15+E15-F15) | H15: =IF(A15="","",'Produtos'!G15) | I15: =IF(A15="","",'Produtos'!H15) | J15: =IF(A15="","",'Produtos'!E15) | K15: =IF(A15="","",G15*J15) | L15: =IF(A15="","",IF(G15<=0,"CRÍTICO",IF(G15<=H15,"REPOR","OK"))) | M15: =IF(A15="","",IF(L15="OK",0,MAX(0,I15-G15))) | N15: =IF(A15="","",IF(H15>0,G15/H15,99)) | O15: =IF(A15="","",IF(L15="OK","",N15+ROW()/100000))
A16: =IF('Produtos'!A16="","",'Produtos'!A16) | B16: =IF(A16="","",'Produtos'!B16) | C16: =IF(A16="","",'Produtos'!C16) | D16: =IF(A16="","",'Produtos'!F16) | E16: =IF(A16="","",SUMIFS('Movimentações'!$F$5:$F$1004,'Movimentações'!$C$5:$C$1004,A16,'Movimentações'!$E$5:$E$1004,"Entrada")) | F16: =IF(A16="","",SUMIFS('Movimentações'!$F$5:$F$1004,'Movimentações'!$C$5:$C$1004,A16,'Movimentações'!$E$5:$E$1004,"Saída")) | G16: =IF(A16="","",D16+E16-F16) | H16: =IF(A16="","",'Produtos'!G16) | I16: =IF(A16="","",'Produtos'!H16) | J16: =IF(A16="","",'Produtos'!E16) | K16: =IF(A16="","",G16*J16) | L16: =IF(A16="","",IF(G16<=0,"CRÍTICO",IF(G16<=H16,"REPOR","OK"))) | M16: =IF(A16="","",IF(L16="OK",0,MAX(0,I16-G16))) | N16: =IF(A16="","",IF(H16>0,G16/H16,99)) | O16: =IF(A16="","",IF(L16="OK","",N16+ROW()/100000))
... A204: =IF('Produtos'!A204="","",'Produtos'!A204) | B204: =IF(A204="","",'Produtos'!B204) | C204: =IF(A204="","",'Produtos'!C204) | D204: =IF(A204="","",'Produtos'!F204) | E204: =IF(A204="","",SUMIFS('Movimentações'!$F$5:$F$1004,'Movimentações'!$C$5:$C$1004,A204,'Movimentações'!$E$5:$E$1004,"Entrada")) | F204: =IF(A204="","",SUMIFS('Movimentações'!$F$5:$F$1004,'Movimentações'!$C$5:$C$1004,A204,'Movimentações'!$E$5:$E$1004,"Saída")) | G204: =IF(A204="","",D204+E204-F204) | H204: =IF(A204="","",'Produtos'!G204) | I204: =IF(A204="","",'Produtos'!H204) | J204: =IF(A204="","",'Produtos'!E204) | K204: =IF(A204="","",G204*J204) | L204: =IF(A204="","",IF(G204<=0,"CRÍTICO",IF(G204<=H204,"REPOR","OK"))) | M204: =IF(A204="","",IF(L204="OK",0,MAX(0,I204-G204))) | N204: =IF(A204="","",IF(H204>0,G204/H204,99)) | O204: =IF(A204="","",IF(L204="OK","",N204+ROW()/100000))

Sheet Relatórios
A1: Almox EO · Relatórios
A2: Relatórios calculados a partir das abas de origem. Também alimentam os indicadores e gráficos do Dashboard. | L2: ÁREA DE APOIO AO DASHBOARD · calculada automaticamente, não editar
A4: 1. Relatório mensal de movimentações | L4: A. Produtos em alerta (mais críticos primeiro)
A5: Mês | B5: Início | C5: Fim | D5: Unidades recebidas | E5: Unidades retiradas | F5: Saldo líquido | G5: Registros de entrada | H5: Registros de saída | I5: Observação | L5: Posição | M5: Linha | N5: Código | O5: Produto | P5: Saldo atual | Q5: Estoque mínimo | R5: Qtd. sugerida | S5: Status
A6: Mai/2025 | B6: 45778 | C6: =EOMONTH(B6,0) | D6: =SUMIFS('Movimentações'!$F$5:$F$1004,'Movimentações'!$E$5:$E$1004,"Entrada",'Movimentações'!$A$5:$A$1004,">="&B6,'Movimentações'!$A$5:$A$1004,"<="&C6) | E6: =SUMIFS('Movimentações'!$F$5:$F$1004,'Movimentações'!$E$5:$E$1004,"Saída",'Movimentações'!$A$5:$A$1004,">="&B6,'Movimentações'!$A$5:$A$1004,"<="&C6) | F6: =D6-E6 | G6: =COUNTIFS('Movimentações'!$E$5:$E$1004,"Entrada",'Movimentações'!$A$5:$A$1004,">="&B6,'Movimentações'!$A$5:$A$1004,"<="&C6) | H6: =COUNTIFS('Movimentações'!$E$5:$E$1004,"Saída",'Movimentações'!$A$5:$A$1004,">="&B6,'Movimentações'!$A$5:$A$1004,"<="&C6) | I6: Mês completo | L6: 1 | M6: =IFERROR(MATCH(SMALL('Estoque'!$O$5:$O$204,L6),'Estoque'!$O$5:$O$204,0),"") | N6: =IF($M6="","",INDEX('Estoque'!$A$5:$A$204,$M6)) | O6: =IF($M6="","",INDEX('Estoque'!$B$5:$B$204,$M6)) | P6: =IF($M6="","",INDEX('Estoque'!$G$5:$G$204,$M6)) | Q6: =IF($M6="","",INDEX('Estoque'!$H$5:$H$204,$M6)) | R6: =IF($M6="","",INDEX('Estoque'!$M$5:$M$204,$M6)) | S6: =IF($M6="","",INDEX('Estoque'!$L$5:$L$204,$M6))
A7: Jun/2025 | B7: 45809 | C7: =EOMONTH(B7,0) | D7: =SUMIFS('Movimentações'!$F$5:$F$1004,'Movimentações'!$E$5:$E$1004,"Entrada",'Movimentações'!$A$5:$A$1004,">="&B7,'Movimentações'!$A$5:$A$1004,"<="&C7) | E7: =SUMIFS('Movimentações'!$F$5:$F$1004,'Movimentações'!$E$5:$E$1004,"Saída",'Movimentações'!$A$5:$A$1004,">="&B7,'Movimentações'!$A$5:$A$1004,"<="&C7) | F7: =D7-E7 | G7: =COUNTIFS('Movimentações'!$E$5:$E$1004,"Entrada",'Movimentações'!$A$5:$A$1004,">="&B7,'Movimentações'!$A$5:$A$1004,"<="&C7) | H7: =COUNTIFS('Movimentações'!$E$5:$E$1004,"Saída",'Movimentações'!$A$5:$A$1004,">="&B7,'Movimentações'!$A$5:$A$1004,"<="&C7) | I7: Mês completo | L7: 2 | M7: =IFERROR(MATCH(SMALL('Estoque'!$O$5:$O$204,L7),'Estoque'!$O$5:$O$204,0),"") | N7: =IF($M7="","",INDEX('Estoque'!$A$5:$A$204,$M7)) | O7: =IF($M7="","",INDEX('Estoque'!$B$5:$B$204,$M7)) | P7: =IF($M7="","",INDEX('Estoque'!$G$5:$G$204,$M7)) | Q7: =IF($M7="","",INDEX('Estoque'!$H$5:$H$204,$M7)) | R7: =IF($M7="","",INDEX('Estoque'!$M$5:$M$204,$M7)) | S7: =IF($M7="","",INDEX('Estoque'!$L$5:$L$204,$M7))
A8: Jul/2025 | B8: 45839 | C8: =EOMONTH(B8,0) | D8: =SUMIFS('Movimentações'!$F$5:$F$1004,'Movimentações'!$E$5:$E$1004,"Entrada",'Movimentações'!$A$5:$A$1004,">="&B8,'Movimentações'!$A$5:$A$1004,"<="&C8) | E8: =SUMIFS('Movimentações'!$F$5:$F$1004,'Movimentações'!$E$5:$E$1004,"Saída",'Movimentações'!$A$5:$A$1004,">="&B8,'Movimentações'!$A$5:$A$1004,"<="&C8) | F8: =D8-E8 | G8: =COUNTIFS('Movimentações'!$E$5:$E$1004,"Entrada",'Movimentações'!$A$5:$A$1004,">="&B8,'Movimentações'!$A$5:$A$1004,"<="&C8) | H8: =COUNTIFS('Movimentações'!$E$5:$E$1004,"Saída",'Movimentações'!$A$5:$A$1004,">="&B8,'Movimentações'!$A$5:$A$1004,"<="&C8) | I8: Mês completo | L8: 3 | M8: =IFERROR(MATCH(SMALL('Estoque'!$O$5:$O$204,L8),'Estoque'!$O$5:$O$204,0),"") | N8: =IF($M8="","",INDEX('Estoque'!$A$5:$A$204,$M8)) | O8: =IF($M8="","",INDEX('Estoque'!$B$5:$B$204,$M8)) | P8: =IF($M8="","",INDEX('Estoque'!$G$5:$G$204,$M8)) | Q8: =IF($M8="","",INDEX('Estoque'!$H$5:$H$204,$M8)) | R8: =IF($M8="","",INDEX('Estoque'!$M$5:$M$204,$M8)) | S8: =IF($M8="","",INDEX('Estoque'!$L$5:$L$204,$M8))
A9: Ago/2025 | B9: 45870 | C9: =EOMONTH(B9,0) | D9: =SUMIFS('Movimentações'!$F$5:$F$1004,'Movimentações'!$E$5:$E$1004,"Entrada",'Movimentações'!$A$5:$A$1004,">="&B9,'Movimentações'!$A$5:$A$1004,"<="&C9) | E9: =SUMIFS('Movimentações'!$F$5:$F$1004,'Movimentações'!$E$5:$E$1004,"Saída",'Movimentações'!$A$5:$A$1004,">="&B9,'Movimentações'!$A$5:$A$1004,"<="&C9) | F9: =D9-E9 | G9: =COUNTIFS('Movimentações'!$E$5:$E$1004,"Entrada",'Movimentações'!$A$5:$A$1004,">="&B9,'Movimentações'!$A$5:$A$1004,"<="&C9) | H9: =COUNTIFS('Movimentações'!$E$5:$E$1004,"Saída",'Movimentações'!$A$5:$A$1004,">="&B9,'Movimentações'!$A$5:$A$1004,"<="&C9) | I9: Mês completo | L9: 4 | M9: =IFERROR(MATCH(SMALL('Estoque'!$O$5:$O$204,L9),'Estoque'!$O$5:$O$204,0),"") | N9: =IF($M9="","",INDEX('Estoque'!$A$5:$A$204,$M9)) | O9: =IF($M9="","",INDEX('Estoque'!$B$5:$B$204,$M9)) | P9: =IF($M9="","",INDEX('Estoque'!$G$5:$G$204,$M9)) | Q9: =IF($M9="","",INDEX('Estoque'!$H$5:$H$204,$M9)) | R9: =IF($M9="","",INDEX('Estoque'!$M$5:$M$204,$M9)) | S9: =IF($M9="","",INDEX('Estoque'!$L$5:$L$204,$M9))
A10: Set/2025 | B10: 45901 | C10: =EOMONTH(B10,0) | D10: =SUMIFS('Movimentações'!$F$5:$F$1004,'Movimentações'!$E$5:$E$1004,"Entrada",'Movimentações'!$A$5:$A$1004,">="&B10,'Movimentações'!$A$5:$A$1004,"<="&C10) | E10: =SUMIFS('Movimentações'!$F$5:$F$1004,'Movimentações'!$E$5:$E$1004,"Saída",'Movimentações'!$A$5:$A$1004,">="&B10,'Movimentações'!$A$5:$A$1004,"<="&C10) | F10: =D10-E10 | G10: =COUNTIFS('Movimentações'!$E$5:$E$1004,"Entrada",'Movimentações'!$A$5:$A$1004,">="&B10,'Movimentações'!$A$5:$A$1004,"<="&C10) | H10: =COUNTIFS('Movimentações'!$E$5:$E$1004,"Saída",'Movimentações'!$A$5:$A$1004,">="&B10,'Movimentações'!$A$5:$A$1004,"<="&C10) | I10: Mês completo | L10: 5 | M10: =IFERROR(MATCH(SMALL('Estoque'!$O$5:$O$204,L10),'Estoque'!$O$5:$O$204,0),"") | N10: =IF($M10="","",INDEX('Estoque'!$A$5:$A$204,$M10)) | O10: =IF($M10="","",INDEX('Estoque'!$B$5:$B$204,$M10)) | P10: =IF($M10="","",INDEX('Estoque'!$G$5:$G$204,$M10)) | Q10: =IF($M10="","",INDEX('Estoque'!$H$5:$H$204,$M10)) | R10: =IF($M10="","",INDEX('Estoque'!$M$5:$M$204,$M10)) | S10: =IF($M10="","",INDEX('Estoque'!$L$5:$L$204,$M10))
A11: Out/2025 | B11: 45931 | C11: =EOMONTH(B11,0) | D11: =SUMIFS('Movimentações'!$F$5:$F$1004,'Movimentações'!$E$5:$E$1004,"Entrada",'Movimentações'!$A$5:$A$1004,">="&B11,'Movimentações'!$A$5:$A$1004,"<="&C11) | E11: =SUMIFS('Movimentações'!$F$5:$F$1004,'Movimentações'!$E$5:$E$1004,"Saída",'Movimentações'!$A$5:$A$1004,">="&B11,'Movimentações'!$A$5:$A$1004,"<="&C11) | F11: =D11-E11 | G11: =COUNTIFS('Movimentações'!$E$5:$E$1004,"Entrada",'Movimentações'!$A$5:$A$1004,">="&B11,'Movimentações'!$A$5:$A$1004,"<="&C11) | H11: =COUNTIFS('Movimentações'!$E$5:$E$1004,"Saída",'Movimentações'!$A$5:$A$1004,">="&B11,'Movimentações'!$A$5:$A$1004,"<="&C11) | I11: Mês completo | L11: 6 | M11: =IFERROR(MATCH(SMALL('Estoque'!$O$5:$O$204,L11),'Estoque'!$O$5:$O$204,0),"") | N11: =IF($M11="","",INDEX('Estoque'!$A$5:$A$204,$M11)) | O11: =IF($M11="","",INDEX('Estoque'!$B$5:$B$204,$M11)) | P11: =IF($M11="","",INDEX('Estoque'!$G$5:$G$204,$M11)) | Q11: =IF($M11="","",INDEX('Estoque'!$H$5:$H$204,$M11)) | R11: =IF($M11="","",INDEX('Estoque'!$M$5:$M$204,$M11)) | S11: =IF($M11="","",INDEX('Estoque'!$L$5:$L$204,$M11))
A12: Total do período | D12: =SUM(D6:D11) | E12: =SUM(E6:E11) | F12: =SUM(F6:F11) | G12: =SUM(G6:G11) | H12: =SUM(H6:H11) | L12: 7 | M12: =IFERROR(MATCH(SMALL('Estoque'!$O$5:$O$204,L12),'Estoque'!$O$5:$O$204,0),"") | N12: =IF($M12="","",INDEX('Estoque'!$A$5:$A$204,$M12)) | O12: =IF($M12="","",INDEX('Estoque'!$B$5:$B$204,$M12)) | P12: =IF($M12="","",INDEX('Estoque'!$G$5:$G$204,$M12)) | Q12: =IF($M12="","",INDEX('Estoque'!$H$5:$H$204,$M12)) | R12: =IF($M12="","",INDEX('Estoque'!$M$5:$M$204,$M12)) | S12: =IF($M12="","",INDEX('Estoque'!$L$5:$L$204,$M12))
L13: 8 | M13: =IFERROR(MATCH(SMALL('Estoque'!$O$5:$O$204,L13),'Estoque'!$O$5:$O$204,0),"") | N13: =IF($M13="","",INDEX('Estoque'!$A$5:$A$204,$M13)) | O13: =IF($M13="","",INDEX('Estoque'!$B$5:$B$204,$M13)) | P13: =IF($M13="","",INDEX('Estoque'!$G$5:$G$204,$M13)) | Q13: =IF($M13="","",INDEX('Estoque'!$H$5:$H$204,$M13)) | R13: =IF($M13="","",INDEX('Estoque'!$M$5:$M$204,$M13)) | S13: =IF($M13="","",INDEX('Estoque'!$L$5:$L$204,$M13))
A15: 2. Relatório por categoria
A16: Categoria | B16: Qtd. de produtos | C16: Valor total do estoque (R$) | D16: Produtos para repor | E16: Participação no valor | L16: B. Movimentações mais recentes
A17: =L30 | B17: =COUNTIF('Produtos'!$C$5:$C$204,A17) | C17: =SUMIF('Estoque'!$C$5:$C$204,A17,'Estoque'!$K$5:$K$204) | D17: =COUNTIFS('Estoque'!$C$5:$C$204,A17,'Estoque'!$L$5:$L$204,"<>OK") | E17: =IF($C$24=0,0,C17/$C$24) | L17: Posição | M17: Linha | N17: Data | O17: Código | P17: Produto | Q17: Tipo | R17: Quantidade | S17: Responsável
A18: =L31 | B18: =COUNTIF('Produtos'!$C$5:$C$204,A18) | C18: =SUMIF('Estoque'!$C$5:$C$204,A18,'Estoque'!$K$5:$K$204) | D18: =COUNTIFS('Estoque'!$C$5:$C$204,A18,'Estoque'!$L$5:$L$204,"<>OK") | E18: =IF($C$24=0,0,C18/$C$24) | L18: 1 | M18: =IFERROR(MATCH(LARGE('Movimentações'!$J$5:$J$1004,L18),'Movimentações'!$J$5:$J$1004,0),"") | N18: =IF($M18="","",INDEX('Movimentações'!$A$5:$A$1004,$M18)) | O18: =IF($M18="","",INDEX('Movimentações'!$C$5:$C$1004,$M18)) | P18: =IF($M18="","",INDEX('Movimentações'!$D$5:$D$1004,$M18)) | Q18: =IF($M18="","",INDEX('Movimentações'!$E$5:$E$1004,$M18)) | R18: =IF($M18="","",INDEX('Movimentações'!$F$5:$F$1004,$M18)) | S18: =IF($M18="","",INDEX('Movimentações'!$G$5:$G$1004,$M18))
A19: =L32 | B19: =COUNTIF('Produtos'!$C$5:$C$204,A19) | C19: =SUMIF('Estoque'!$C$5:$C$204,A19,'Estoque'!$K$5:$K$204) | D19: =COUNTIFS('Estoque'!$C$5:$C$204,A19,'Estoque'!$L$5:$L$204,"<>OK") | E19: =IF($C$24=0,0,C19/$C$24) | L19: 2 | M19: =IFERROR(MATCH(LARGE('Movimentações'!$J$5:$J$1004,L19),'Movimentações'!$J$5:$J$1004,0),"") | N19: =IF($M19="","",INDEX('Movimentações'!$A$5:$A$1004,$M19)) | O19: =IF($M19="","",INDEX('Movimentações'!$C$5:$C$1004,$M19)) | P19: =IF($M19="","",INDEX('Movimentações'!$D$5:$D$1004,$M19)) | Q19: =IF($M19="","",INDEX('Movimentações'!$E$5:$E$1004,$M19)) | R19: =IF($M19="","",INDEX('Movimentações'!$F$5:$F$1004,$M19)) | S19: =IF($M19="","",INDEX('Movimentações'!$G$5:$G$1004,$M19))
A20: =L33 | B20: =COUNTIF('Produtos'!$C$5:$C$204,A20) | C20: =SUMIF('Estoque'!$C$5:$C$204,A20,'Estoque'!$K$5:$K$204) | D20: =COUNTIFS('Estoque'!$C$5:$C$204,A20,'Estoque'!$L$5:$L$204,"<>OK") | E20: =IF($C$24=0,0,C20/$C$24) | L20: 3 | M20: =IFERROR(MATCH(LARGE('Movimentações'!$J$5:$J$1004,L20),'Movimentações'!$J$5:$J$1004,0),"") | N20: =IF($M20="","",INDEX('Movimentações'!$A$5:$A$1004,$M20)) | O20: =IF($M20="","",INDEX('Movimentações'!$C$5:$C$1004,$M20)) | P20: =IF($M20="","",INDEX('Movimentações'!$D$5:$D$1004,$M20)) | Q20: =IF($M20="","",INDEX('Movimentações'!$E$5:$E$1004,$M20)) | R20: =IF($M20="","",INDEX('Movimentações'!$F$5:$F$1004,$M20)) | S20: =IF($M20="","",INDEX('Movimentações'!$G$5:$G$1004,$M20))
A21: =L34 | B21: =COUNTIF('Produtos'!$C$5:$C$204,A21) | C21: =SUMIF('Estoque'!$C$5:$C$204,A21,'Estoque'!$K$5:$K$204) | D21: =COUNTIFS('Estoque'!$C$5:$C$204,A21,'Estoque'!$L$5:$L$204,"<>OK") | E21: =IF($C$24=0,0,C21/$C$24) | L21: 4 | M21: =IFERROR(MATCH(LARGE('Movimentações'!$J$5:$J$1004,L21),'Movimentações'!$J$5:$J$1004,0),"") | N21: =IF($M21="","",INDEX('Movimentações'!$A$5:$A$1004,$M21)) | O21: =IF($M21="","",INDEX('Movimentações'!$C$5:$C$1004,$M21)) | P21: =IF($M21="","",INDEX('Movimentações'!$D$5:$D$1004,$M21)) | Q21: =IF($M21="","",INDEX('Movimentações'!$E$5:$E$1004,$M21)) | R21: =IF($M21="","",INDEX('Movimentações'!$F$5:$F$1004,$M21)) | S21: =IF($M21="","",INDEX('Movimentações'!$G$5:$G$1004,$M21))
A22: =L35 | B22: =COUNTIF('Produtos'!$C$5:$C$204,A22) | C22: =SUMIF('Estoque'!$C$5:$C$204,A22,'Estoque'!$K$5:$K$204) | D22: =COUNTIFS('Estoque'!$C$5:$C$204,A22,'Estoque'!$L$5:$L$204,"<>OK") | E22: =IF($C$24=0,0,C22/$C$24) | L22: 5 | M22: =IFERROR(MATCH(LARGE('Movimentações'!$J$5:$J$1004,L22),'Movimentações'!$J$5:$J$1004,0),"") | N22: =IF($M22="","",INDEX('Movimentações'!$A$5:$A$1004,$M22)) | O22: =IF($M22="","",INDEX('Movimentações'!$C$5:$C$1004,$M22)) | P22: =IF($M22="","",INDEX('Movimentações'!$D$5:$D$1004,$M22)) | Q22: =IF($M22="","",INDEX('Movimentações'!$E$5:$E$1004,$M22)) | R22: =IF($M22="","",INDEX('Movimentações'!$F$5:$F$1004,$M22)) | S22: =IF($M22="","",INDEX('Movimentações'!$G$5:$G$1004,$M22))
A23: =L36 | B23: =COUNTIF('Produtos'!$C$5:$C$204,A23) | C23: =SUMIF('Estoque'!$C$5:$C$204,A23,'Estoque'!$K$5:$K$204) | D23: =COUNTIFS('Estoque'!$C$5:$C$204,A23,'Estoque'!$L$5:$L$204,"<>OK") | E23: =IF($C$24=0,0,C23/$C$24) | L23: 6 | M23: =IFERROR(MATCH(LARGE('Movimentações'!$J$5:$J$1004,L23),'Movimentações'!$J$5:$J$1004,0),"") | N23: =IF($M23="","",INDEX('Movimentações'!$A$5:$A$1004,$M23)) | O23: =IF($M23="","",INDEX('Movimentações'!$C$5:$C$1004,$M23)) | P23: =IF($M23="","",INDEX('Movimentações'!$D$5:$D$1004,$M23)) | Q23: =IF($M23="","",INDEX('Movimentações'!$E$5:$E$1004,$M23)) | R23: =IF($M23="","",INDEX('Movimentações'!$F$5:$F$1004,$M23)) | S23: =IF($M23="","",INDEX('Movimentações'!$G$5:$G$1004,$M23))
A24: Total | B24: =SUM(B17:B23) | C24: =SUM(C17:C23) | D24: =SUM(D17:D23) | E24: =SUM(E17:E23) | L24: 7 | M24: =IFERROR(MATCH(LARGE('Movimentações'!$J$5:$J$1004,L24),'Movimentações'!$J$5:$J$1004,0),"") | N24: =IF($M24="","",INDEX('Movimentações'!$A$5:$A$1004,$M24)) | O24: =IF($M24="","",INDEX('Movimentações'!$C$5:$C$1004,$M24)) | P24: =IF($M24="","",INDEX('Movimentações'!$D$5:$D$1004,$M24)) | Q24: =IF($M24="","",INDEX('Movimentações'!$E$5:$E$1004,$M24)) | R24: =IF($M24="","",INDEX('Movimentações'!$F$5:$F$1004,$M24)) | S24: =IF($M24="","",INDEX('Movimentações'!$G$5:$G$1004,$M24))
L25: 8 | M25: =IFERROR(MATCH(LARGE('Movimentações'!$J$5:$J$1004,L25),'Movimentações'!$J$5:$J$1004,0),"") | N25: =IF($M25="","",INDEX('Movimentações'!$A$5:$A$1004,$M25)) | O25: =IF($M25="","",INDEX('Movimentações'!$C$5:$C$1004,$M25)) | P25: =IF($M25="","",INDEX('Movimentações'!$D$5:$D$1004,$M25)) | Q25: =IF($M25="","",INDEX('Movimentações'!$E$5:$E$1004,$M25)) | R25: =IF($M25="","",INDEX('Movimentações'!$F$5:$F$1004,$M25)) | S25: =IF($M25="","",INDEX('Movimentações'!$G$5:$G$1004,$M25))
A27: 3. Top 10 produtos mais movimentados
A28: Produto | B28: Posição | C28: Código | D28: Total de entradas | E28: Total de saídas | F28: Quantidade total movimentada | L28: C. Listas de opções (usadas nas validações)
A29: =IF(C29="","",INDEX($B$42:$B$241,IFERROR(MATCH(LARGE($H$42:$H$241,1),$H$42:$H$241,0),0))) | B29: 1 | C29: =IF(IFERROR(MATCH(LARGE($H$42:$H$241,1),$H$42:$H$241,0),0)=0,"",INDEX($A$42:$A$241,IFERROR(MATCH(LARGE($H$42:$H$241,1),$H$42:$H$241,0),0))) | D29: =IF(C29="","",INDEX($D$42:$D$241,IFERROR(MATCH(LARGE($H$42:$H$241,1),$H$42:$H$241,0),0))) | E29: =IF(C29="","",INDEX($E$42:$E$241,IFERROR(MATCH(LARGE($H$42:$H$241,1),$H$42:$H$241,0),0))) | F29: =IF(C29="","",INDEX($F$42:$F$241,IFERROR(MATCH(LARGE($H$42:$H$241,1),$H$42:$H$241,0),0))) | L29: Categorias | O29: Tipos | P29: Responsáveis
A30: =IF(C30="","",INDEX($B$42:$B$241,IFERROR(MATCH(LARGE($H$42:$H$241,2),$H$42:$H$241,0),0))) | B30: 2 | C30: =IF(IFERROR(MATCH(LARGE($H$42:$H$241,2),$H$42:$H$241,0),0)=0,"",INDEX($A$42:$A$241,IFERROR(MATCH(LARGE($H$42:$H$241,2),$H$42:$H$241,0),0))) | D30: =IF(C30="","",INDEX($D$42:$D$241,IFERROR(MATCH(LARGE($H$42:$H$241,2),$H$42:$H$241,0),0))) | E30: =IF(C30="","",INDEX($E$42:$E$241,IFERROR(MATCH(LARGE($H$42:$H$241,2),$H$42:$H$241,0),0))) | F30: =IF(C30="","",INDEX($F$42:$F$241,IFERROR(MATCH(LARGE($H$42:$H$241,2),$H$42:$H$241,0),0))) | L30: Fibra Óptica | O30: Entrada | P30: Elinaldo Oliveira
A31: =IF(C31="","",INDEX($B$42:$B$241,IFERROR(MATCH(LARGE($H$42:$H$241,3),$H$42:$H$241,0),0))) | B31: 3 | C31: =IF(IFERROR(MATCH(LARGE($H$42:$H$241,3),$H$42:$H$241,0),0)=0,"",INDEX($A$42:$A$241,IFERROR(MATCH(LARGE($H$42:$H$241,3),$H$42:$H$241,0),0))) | D31: =IF(C31="","",INDEX($D$42:$D$241,IFERROR(MATCH(LARGE($H$42:$H$241,3),$H$42:$H$241,0),0))) | E31: =IF(C31="","",INDEX($E$42:$E$241,IFERROR(MATCH(LARGE($H$42:$H$241,3),$H$42:$H$241,0),0))) | F31: =IF(C31="","",INDEX($F$42:$F$241,IFERROR(MATCH(LARGE($H$42:$H$241,3),$H$42:$H$241,0),0))) | L31: Equipamentos de Rede | O31: Saída | P31: Bruno Estevam
A32: =IF(C32="","",INDEX($B$42:$B$241,IFERROR(MATCH(LARGE($H$42:$H$241,4),$H$42:$H$241,0),0))) | B32: 4 | C32: =IF(IFERROR(MATCH(LARGE($H$42:$H$241,4),$H$42:$H$241,0),0)=0,"",INDEX($A$42:$A$241,IFERROR(MATCH(LARGE($H$42:$H$241,4),$H$42:$H$241,0),0))) | D32: =IF(C32="","",INDEX($D$42:$D$241,IFERROR(MATCH(LARGE($H$42:$H$241,4),$H$42:$H$241,0),0))) | E32: =IF(C32="","",INDEX($E$42:$E$241,IFERROR(MATCH(LARGE($H$42:$H$241,4),$H$42:$H$241,0),0))) | F32: =IF(C32="","",INDEX($F$42:$F$241,IFERROR(MATCH(LARGE($H$42:$H$241,4),$H$42:$H$241,0),0))) | L32: Ferramentas | P32: Rosilene Barbosa
A33: =IF(C33="","",INDEX($B$42:$B$241,IFERROR(MATCH(LARGE($H$42:$H$241,5),$H$42:$H$241,0),0))) | B33: 5 | C33: =IF(IFERROR(MATCH(LARGE($H$42:$H$241,5),$H$42:$H$241,0),0)=0,"",INDEX($A$42:$A$241,IFERROR(MATCH(LARGE($H$42:$H$241,5),$H$42:$H$241,0),0))) | D33: =IF(C33="","",INDEX($D$42:$D$241,IFERROR(MATCH(LARGE($H$42:$H$241,5),$H$42:$H$241,0),0))) | E33: =IF(C33="","",INDEX($E$42:$E$241,IFERROR(MATCH(LARGE($H$42:$H$241,5),$H$42:$H$241,0),0))) | F33: =IF(C33="","",INDEX($F$42:$F$241,IFERROR(MATCH(LARGE($H$42:$H$241,5),$H$42:$H$241,0),0))) | L33: Embalagem e Expedição | P33: Wellington Farias
A34: =IF(C34="","",INDEX($B$42:$B$241,IFERROR(MATCH(LARGE($H$42:$H$241,6),$H$42:$H$241,0),0))) | B34: 6 | C34: =IF(IFERROR(MATCH(LARGE($H$42:$H$241,6),$H$42:$H$241,0),0)=0,"",INDEX($A$42:$A$241,IFERROR(MATCH(LARGE($H$42:$H$241,6),$H$42:$H$241,0),0))) | D34: =IF(C34="","",INDEX($D$42:$D$241,IFERROR(MATCH(LARGE($H$42:$H$241,6),$H$42:$H$241,0),0))) | E34: =IF(C34="","",INDEX($E$42:$E$241,IFERROR(MATCH(LARGE($H$42:$H$241,6),$H$42:$H$241,0),0))) | F34: =IF(C34="","",INDEX($F$42:$F$241,IFERROR(MATCH(LARGE($H$42:$H$241,6),$H$42:$H$241,0),0))) | L34: EPI | P34: Rodrigo Oliveira
A35: =IF(C35="","",INDEX($B$42:$B$241,IFERROR(MATCH(LARGE($H$42:$H$241,7),$H$42:$H$241,0),0))) | B35: 7 | C35: =IF(IFERROR(MATCH(LARGE($H$42:$H$241,7),$H$42:$H$241,0),0)=0,"",INDEX($A$42:$A$241,IFERROR(MATCH(LARGE($H$42:$H$241,7),$H$42:$H$241,0),0))) | D35: =IF(C35="","",INDEX($D$42:$D$241,IFERROR(MATCH(LARGE($H$42:$H$241,7),$H$42:$H$241,0),0))) | E35: =IF(C35="","",INDEX($E$42:$E$241,IFERROR(MATCH(LARGE($H$42:$H$241,7),$H$42:$H$241,0),0))) | F35: =IF(C35="","",INDEX($F$42:$F$241,IFERROR(MATCH(LARGE($H$42:$H$241,7),$H$42:$H$241,0),0))) | L35: Materiais Elétricos | P35: Eliane Cunha
A36: =IF(C36="","",INDEX($B$42:$B$241,IFERROR(MATCH(LARGE($H$42:$H$241,8),$H$42:$H$241,0),0))) | B36: 8 | C36: =IF(IFERROR(MATCH(LARGE($H$42:$H$241,8),$H$42:$H$241,0),0)=0,"",INDEX($A$42:$A$241,IFERROR(MATCH(LARGE($H$42:$H$241,8),$H$42:$H$241,0),0))) | D36: =IF(C36="","",INDEX($D$42:$D$241,IFERROR(MATCH(LARGE($H$42:$H$241,8),$H$42:$H$241,0),0))) | E36: =IF(C36="","",INDEX($E$42:$E$241,IFERROR(MATCH(LARGE($H$42:$H$241,8),$H$42:$H$241,0),0))) | F36: =IF(C36="","",INDEX($F$42:$F$241,IFERROR(MATCH(LARGE($H$42:$H$241,8),$H$42:$H$241,0),0))) | L36: Escritório e Limpeza
A37: =IF(C37="","",INDEX($B$42:$B$241,IFERROR(MATCH(LARGE($H$42:$H$241,9),$H$42:$H$241,0),0))) | B37: 9 | C37: =IF(IFERROR(MATCH(LARGE($H$42:$H$241,9),$H$42:$H$241,0),0)=0,"",INDEX($A$42:$A$241,IFERROR(MATCH(LARGE($H$42:$H$241,9),$H$42:$H$241,0),0))) | D37: =IF(C37="","",INDEX($D$42:$D$241,IFERROR(MATCH(LARGE($H$42:$H$241,9),$H$42:$H$241,0),0))) | E37: =IF(C37="","",INDEX($E$42:$E$241,IFERROR(MATCH(LARGE($H$42:$H$241,9),$H$42:$H$241,0),0))) | F37: =IF(C37="","",INDEX($F$42:$F$241,IFERROR(MATCH(LARGE($H$42:$H$241,9),$H$42:$H$241,0),0)))
A38: =IF(C38="","",INDEX($B$42:$B$241,IFERROR(MATCH(LARGE($H$42:$H$241,10),$H$42:$H$241,0),0))) | B38: 10 | C38: =IF(IFERROR(MATCH(LARGE($H$42:$H$241,10),$H$42:$H$241,0),0)=0,"",INDEX($A$42:$A$241,IFERROR(MATCH(LARGE($H$42:$H$241,10),$H$42:$H$241,0),0))) | D38: =IF(C38="","",INDEX($D$42:$D$241,IFERROR(MATCH(LARGE($H$42:$H$241,10),$H$42:$H$241,0),0))) | E38: =IF(C38="","",INDEX($E$42:$E$241,IFERROR(MATCH(LARGE($H$42:$H$241,10),$H$42:$H$241,0),0))) | F38: =IF(C38="","",INDEX($F$42:$F$241,IFERROR(MATCH(LARGE($H$42:$H$241,10),$H$42:$H$241,0),0)))
A40: 4. Movimentação por produto (use o filtro para ordenar; a coluna Ranking indica os mais movimentados)
A41: Código | B41: Produto | C41: Categoria | D41: Total de entradas | E41: Total de saídas | F41: Quantidade total movimentada | G41: Ranking | H41: Chave (auxiliar)
A42: =IF('Estoque'!A5="","",'Estoque'!A5) | B42: =IF(A42="","",'Estoque'!B5) | C42: =IF(A42="","",'Estoque'!C5) | D42: =IF(A42="","",'Estoque'!E5) | E42: =IF(A42="","",'Estoque'!F5) | F42: =IF(A42="","",D42+E42) | G42: =IF(A42="","",RANK(F42,$F$42:$F$241)) | H42: =IF(A42="","",F42-ROW()/1000000)
A43: =IF('Estoque'!A6="","",'Estoque'!A6) | B43: =IF(A43="","",'Estoque'!B6) | C43: =IF(A43="","",'Estoque'!C6) | D43: =IF(A43="","",'Estoque'!E6) | E43: =IF(A43="","",'Estoque'!F6) | F43: =IF(A43="","",D43+E43) | G43: =IF(A43="","",RANK(F43,$F$42:$F$241)) | H43: =IF(A43="","",F43-ROW()/1000000)
A44: =IF('Estoque'!A7="","",'Estoque'!A7) | B44: =IF(A44="","",'Estoque'!B7) | C44: =IF(A44="","",'Estoque'!C7) | D44: =IF(A44="","",'Estoque'!E7) | E44: =IF(A44="","",'Estoque'!F7) | F44: =IF(A44="","",D44+E44) | G44: =IF(A44="","",RANK(F44,$F$42:$F$241)) | H44: =IF(A44="","",F44-ROW()/1000000)
...

Sheet Leia-me
B2: Almox EO · Leia-me
B3: Guia de uso do projeto · Autor: Elinaldo Oliveira do Nascimento · Projeto pessoal de portfólio · Dados 100% fictícios
B5: 1. Objetivo do projeto
B6: Resumo | C6: O Almox EO simula o almoxarifado da empresa fictícia Conecta Log Serviços e Telecom, que atende a área de logística (embalagem e expedição) e equipes de campo de redes de fibra óptica. A planilha controla o cadastro de produtos, registra entradas e saídas, calcula saldos automaticamente, indica a necessidade de reposição e apresenta indicadores em um dashboard.
B7: Ferramenta | C7: Somente Microsoft Excel: fórmulas, validação de dados, formatação condicional, filtros e gráficos. Sem macros, VBA ou serviços externos.
B8: Dados | C8: Todos os produtos, fornecedores, pessoas, valores e movimentações são fictícios e servem apenas para demonstração. Período simulado: 01/05/2025 a 31/10/2025.
B10: 2. Para que serve cada aba
B11: Dashboard | C11: Tela inicial. Mostra indicadores (cartões), gráficos, alertas de reposição e as últimas movimentações. Escolha o mês de análise na célula ao lado de 'MÊS DE ANÁLISE'.
B12: Produtos | C12: Cadastro dos itens: código, nome, categoria, fornecedor, custo, estoque inicial, mínimo, máximo e localização.
B13: Movimentações | C13: Histórico de entradas e saídas. Cada linha é uma operação com ID único.
B14: Estoque | C14: Posição atual de cada produto, totalmente calculada. Mostra saldo, valor, status e sugestão de compra.
B15: Relatórios | C15: Relatório mensal, por categoria, Top 10 mais movimentados e movimentação por produto. À direita fica a área de apoio usada pelo Dashboard e as listas das validações.
B16: Leia-me | C16: Este guia.
B18: 3. Cores das células
B19: Branco | C19: Células de digitação (dados de entrada).
B20: Cinza-azulado | C20: Células com fórmulas. Não digite nelas: são preenchidas automaticamente.
B21: Cabeçalho cinza-claro | C21: Colunas auxiliares usadas para ordenar listas do Dashboard.
B23: 4. Como cadastrar um produto
B24: Passo 1 | C24: Na aba Produtos, vá até a primeira linha vazia abaixo do último item.
B25: Passo 2 | C25: Digite um código novo e único (ex.: P031). Códigos repetidos são bloqueados.
B26: Passo 3 | C26: Preencha nome, escolha a categoria na lista, informe fornecedor e custo unitário (R$).
B27: Passo 4 | C27: Informe estoque inicial, mínimo e máximo (inteiros; o máximo deve ser maior que o mínimo).
B28: Passo 5 | C28: Informe a localização no padrão Rua-Prateleira-Nível, ex.: A-01-01. O item aparece sozinho na aba Estoque.
B30: 5. Como registrar entradas e saídas
B31: Passo 1 | C31: Na aba Movimentações, use a primeira linha vazia.
B32: Passo 2 | C32: Digite a data e o ID indicado em 'Próximo ID' (topo da aba).
B33: Passo 3 | C33: Escolha o código do produto na lista. O nome aparece automaticamente.
B34: Passo 4 | C34: Escolha o tipo (Entrada ou Saída), a quantidade (inteiro maior que zero), o responsável e uma observação.
B35: Conferência | C35: A coluna 'Saldo do produto no fim do dia' mostra o saldo após a operação. Se ficar negativo, a célula fica vermelha: a saída é maior do que havia em estoque e deve ser revisada.
B37: 6. Como funcionam os cálculos
B38: Saldo atual | C38: Saldo = Estoque inicial + Total de entradas − Total de saídas. O estoque inicial é o saldo em 01/05/2025.
B39: Valor em estoque | C39: Valor = Saldo atual × Custo unitário. O custo é fixo por produto (não há custo médio).
B40: Status | C40: CRÍTICO: saldo zerado ou negativo. REPOR: saldo maior que zero e menor ou igual ao estoque mínimo. OK: saldo acima do estoque mínimo.
B41: Sugestão de reposição | C41: Para itens CRÍTICO ou REPOR: Estoque máximo − Saldo atual (nunca negativo). Para itens OK: 0. Assim a compra recompõe o estoque até o nível máximo definido no cadastro.
B42: Prioridade dos alertas | C42: Os alertas são ordenados pela cobertura (saldo ÷ mínimo): quanto menor, mais urgente. Itens zerados aparecem primeiro.
B44: 7. Como interpretar o Dashboard
B45: Cartões | C45: Produtos cadastrados, valor total em estoque, itens em alerta, entradas e saídas do mês escolhido e total de movimentações registradas.
B46: Gráfico de colunas | C46: Compara unidades recebidas (ciano) e retiradas (laranja) por mês.
B47: Gráfico de rosca | C47: Participação de cada categoria no valor total do estoque. A soma é igual ao cartão 'Valor em estoque'.
B48: Gráfico de barras | C48: Até 8 produtos em alerta, com a quantidade sugerida para compra, do mais urgente para o menos urgente.
...
